Booking 5 status updated to paid via success page
Payment record created for booking 5
Booking 6 status updated to paid via success page
Payment record created for booking 6
Booking 7 status updated to paid via success page
Payment record created for booking 7
Stripe SECRET key invalid or quoted. Raw value: ''
Stripe SECRET key invalid or quoted. Raw value: ''
Stripe SECRET key invalid or quoted. Raw value: ''
Stripe SECRET key invalid or quoted. Raw value: ''
Stripe SECRET key invalid or quoted. Raw value: ''
Stripe SECRET key invalid or quoted. Raw value: ''
Stripe SECRET key invalid or quoted. Raw value: ''
Stripe SECRET key invalid or quoted. Raw value: ''
Stripe SECRET key invalid or quoted. Raw value: ''
Stripe SECRET key invalid or quoted. Raw value: ''
Stripe SECRET key invalid or quoted. Raw value: ''
Stripe SECRET key invalid or quoted. Raw value: ''
Stripe SECRET key invalid or quoted. Raw value: ''
Stripe SECRET key invalid or quoted. Raw value: ''
Stripe SECRET key invalid or quoted. Raw value: ''
Stripe SECRET key invalid or quoted. Raw value: ''
Stripe SECRET key invalid or quoted. Raw value: ''
Stripe SECRET key invalid or quoted. Raw value: ''
Booking 11 status updated to paid via success page
Payment record created for booking 11
Stripe checkout session creation failed (booking_id=17)
Traceback (most recent call last):
  File "C:\Users\ENG\AppData\Local\Programs\Python\Python310\lib\site-packages\urllib3\connection.py", line 198, in _new_conn
    sock = connection.create_connection(
  File "C:\Users\ENG\AppData\Local\Programs\Python\Python310\lib\site-packages\urllib3\util\connection.py", line 60, in create_connection
    for res in socket.getaddrinfo(host, port, family, socket.SOCK_STREAM):
  File "C:\Users\ENG\AppData\Local\Programs\Python\Python310\lib\socket.py", line 955, in getaddrinfo
    for res in _socket.getaddrinfo(host, port, family, type, proto, flags):
socket.gaierror: [Errno 11001] getaddrinfo failed

The above exception was the direct cause of the following exception:

Traceback (most recent call last):
  File "C:\Users\ENG\AppData\Local\Programs\Python\Python310\lib\site-packages\urllib3\connectionpool.py", line 787, in urlopen
    response = self._make_request(
  File "C:\Users\ENG\AppData\Local\Programs\Python\Python310\lib\site-packages\urllib3\connectionpool.py", line 488, in _make_request
    raise new_e
  File "C:\Users\ENG\AppData\Local\Programs\Python\Python310\lib\site-packages\urllib3\connectionpool.py", line 464, in _make_request
    self._validate_conn(conn)
  File "C:\Users\ENG\AppData\Local\Programs\Python\Python310\lib\site-packages\urllib3\connectionpool.py", line 1093, in _validate_conn
    conn.connect()
  File "C:\Users\ENG\AppData\Local\Programs\Python\Python310\lib\site-packages\urllib3\connection.py", line 753, in connect
    self.sock = sock = self._new_conn()
  File "C:\Users\ENG\AppData\Local\Programs\Python\Python310\lib\site-packages\urllib3\connection.py", line 205, in _new_conn
    raise NameResolutionError(self.host, self, e) from e
urllib3.exceptions.NameResolutionError: <urllib3.connection.HTTPSConnection object at 0x00000220A4199960>: Failed to resolve 'api.stripe.com' ([Errno 11001] getaddrinfo failed)

The above exception was the direct cause of the following exception:

Traceback (most recent call last):
  File "C:\Users\ENG\AppData\Local\Programs\Python\Python310\lib\site-packages\requests\adapters.py", line 667, in send
    resp = conn.urlopen(
  File "C:\Users\ENG\AppData\Local\Programs\Python\Python310\lib\site-packages\urllib3\connectionpool.py", line 841, in urlopen
    retries = retries.increment(
  File "C:\Users\ENG\AppData\Local\Programs\Python\Python310\lib\site-packages\urllib3\util\retry.py", line 519, in increment
    raise MaxRetryError(_pool, url, reason) from reason  # type: ignore[arg-type]
urllib3.exceptions.MaxRetryError: HTTPSConnectionPool(host='api.stripe.com', port=443): Max retries exceeded with url: /v1/checkout/sessions (Caused by NameResolutionError("<urllib3.connection.HTTPSConnection object at 0x00000220A4199960>: Failed to resolve 'api.stripe.com' ([Errno 11001] getaddrinfo failed)"))

During handling of the above exception, another exception occurred:

Traceback (most recent call last):
  File "C:\Users\ENG\AppData\Local\Programs\Python\Python310\lib\site-packages\stripe\_http_client.py", line 685, in _request_internal
    result = cast(
  File "C:\Users\ENG\AppData\Local\Programs\Python\Python310\lib\site-packages\requests\sessions.py", line 589, in request
    resp = self.send(prep, **send_kwargs)
  File "C:\Users\ENG\AppData\Local\Programs\Python\Python310\lib\site-packages\requests\sessions.py", line 703, in send
    r = adapter.send(request, **kwargs)
  File "C:\Users\ENG\AppData\Local\Programs\Python\Python310\lib\site-packages\requests\adapters.py", line 700, in send
    raise ConnectionError(e, request=request)
requests.exceptions.ConnectionError: HTTPSConnectionPool(host='api.stripe.com', port=443): Max retries exceeded with url: /v1/checkout/sessions (Caused by NameResolutionError("<urllib3.connection.HTTPSConnection object at 0x00000220A4199960>: Failed to resolve 'api.stripe.com' ([Errno 11001] getaddrinfo failed)"))

The above exception was the direct cause of the following exception:

Traceback (most recent call last):
  File "E:\JYGKUI\sakanak\payments\views.py", line 32, in create_checkout_session
    session = stripe.checkout.Session.create(
  File "C:\Users\ENG\AppData\Local\Programs\Python\Python310\lib\site-packages\stripe\checkout\_session.py", line 4932, in create
    cls._static_request(
  File "C:\Users\ENG\AppData\Local\Programs\Python\Python310\lib\site-packages\stripe\_api_resource.py", line 172, in _static_request
    return _APIRequestor._global_instance().request(
  File "C:\Users\ENG\AppData\Local\Programs\Python\Python310\lib\site-packages\stripe\_api_requestor.py", line 187, in request
    rbody, rcode, rheaders = requestor.request_raw(
  File "C:\Users\ENG\AppData\Local\Programs\Python\Python310\lib\site-packages\stripe\_api_requestor.py", line 719, in request_raw
    ) = self._get_http_client().request_with_retries(
  File "C:\Users\ENG\AppData\Local\Programs\Python\Python310\lib\site-packages\stripe\_http_client.py", line 309, in request_with_retries
    return self._request_with_retries_internal(
  File "C:\Users\ENG\AppData\Local\Programs\Python\Python310\lib\site-packages\stripe\_http_client.py", line 396, in _request_with_retries_internal
    raise connection_error
  File "C:\Users\ENG\AppData\Local\Programs\Python\Python310\lib\site-packages\stripe\_http_client.py", line 363, in _request_with_retries_internal
    response = self.request(method, url, headers, post_data)
  File "C:\Users\ENG\AppData\Local\Programs\Python\Python310\lib\site-packages\stripe\_http_client.py", line 623, in request
    return self._request_internal(
  File "C:\Users\ENG\AppData\Local\Programs\Python\Python310\lib\site-packages\stripe\_http_client.py", line 717, in _request_internal
    self._handle_request_error(e)
  File "C:\Users\ENG\AppData\Local\Programs\Python\Python310\lib\site-packages\stripe\_http_client.py", line 772, in _handle_request_error
    raise APIConnectionError(msg, should_retry=should_retry) from e
stripe._error.APIConnectionError: Unexpected error communicating with Stripe.  If this problem persists,
let us know at support@stripe.com.

(Network error: ConnectionError: HTTPSConnectionPool(host='api.stripe.com', port=443): Max retries exceeded with url: /v1/checkout/sessions (Caused by NameResolutionError("<urllib3.connection.HTTPSConnection object at 0x00000220A4199960>: Failed to resolve 'api.stripe.com' ([Errno 11001] getaddrinfo failed)")))
